Workbook

Sheet AW1
A1: NO | B1: NAMA LENGKAP | C1: EMAIL | D1: NO KONTAK YANG BISA DIHUB | E1: JENIS KELAMIN | F1: JENJANG | G1: (BOARDING/FULLDAY) | H1: KELAS | I1: PROGRAM | J1: PEMINATAN | L1: =NOW() -> 46276.776
A2: 1 | B2: Sakha Alkhalifi Harfian | C2: nerissaines@gmail.com | D2: 85773552375 | E2: laki-laki | F2: TK-B | G2: Fullday | H2: TK-B | I2: INT | J2: - | M2: AW1 | N2: AW3 | O2: AW4 | P2: AW5 | Q2: AW8 | R2: AW16
A3: 2 | L3: PG | M3: =countif(F:F,$L3) -> 0
A4: 3 | L4: TK-A | M4: =countif(F:F,$L4) -> 0
A5: 4 | L5: TK-B | M5: =countif(F:F,$L5) -> 1
A6: 5 | L6: SD | M6: =countif(F:F,$L6) -> 0 | O6: =COUNTIF('AW4'!F:F,$L6) -> #REF! | P6: =COUNTIF('AW5'!F:F,L6) -> #REF! | Q6: =COUNTIF('AW8'!F:F,$L6) -> #REF! | R6: =COUNTIF('AW16'!F:F,$L6) -> #REF!
A7: 6 | L7: SMP | M7: =countif(F:F,$L7) -> 0 | N7: =countif(AW1_!F:F,$L7) -> 34 | O7: =COUNTIF('AW4'!F:F,$L7) -> #REF! | Q7: =COUNTIF('AW8'!F:F,$L7) -> #REF! | R7: =COUNTIF('AW16'!F:F,$L7) -> #REF!
A8: 7 | L8: SMA | M8: =countif(F:F,$L8) -> 0 | N8: =countif(AW1_!F:F,$L8) -> 18 | O8: =COUNTIF('AW4'!F:F,$L8) -> #REF! | Q8: =COUNTIF('AW8'!F:F,$L8) -> #REF! | R8: =COUNTIF('AW16'!F:F,$L8) -> #REF!
A9: 8
A10: 9 | L10: TOTAL | M10: =sum(M3:M8) -> 1 | N10: =sum(N3:N8) -> 52 | O10: =sum(O3:O8) -> #REF! | P10: =sum(P3:P8) -> #REF! | Q10: =sum(Q3:Q8) -> #REF! | R10: =sum(R3:R8) -> #REF!
A11: 10
A12: 11 | M12: SABTU, 14 SEPT 2024
A13: 12 | M13: AHAD, 15 SEPT 2024
A14: 13
A15: 14
A16: 15
A17: 16
A18: 17
A19: 18
A20: 19
A21: 20
A22: 21
A23: 22
A24: 23
A25: 24
... A125: 124

Sheet REKAP
B2: =NOW() -> 46276.776
C3: AW1 | D3: AW3 | E3: AW4 | G3: H-TOTAL | J3: AW5 | K3: AW7 | L3: AW8 | M3: AW10 | N3: AW12 | O3: AW13 | P3: AW14 | Q3: AW15 | R3: AW16 | S3: AW20 | T3: AW21 | U3: AW22 | V3: AW23 | W3: AW24 | X3: AW27 | Y3: AW28 | Z3: AW29 | AA3: AW31 | AB3: AW32
B4: PG | C4: =AW1_!F162 -> 7 | G4: =SUM(C4:E4) -> 7 | I4: PG
B5: TK-A | C5: =AW1_!F163 -> 16 | G5: =SUM(C5:E5) -> 16 | I5: TK-A
B6: TK-B | C6: =AW1_!F164 -> 6 | G6: =SUM(C6:E6) -> 6 | I6: TK-B
B7: SD | C7: =AW1_!F165 -> 78 | E7: ='AW4'!F91 -> 67 | G7: =SUM(C7:E7) -> 145 | I7: SD | J7: ='AW5'!F31 -> 26 | K7: ='AW7'!F23 -> 5 | P7: ='AW14'!F83 -> 52 | Q7: ='AW15'!F99 -> 62 | R7: ='AW16'!F80 -> 49 | Y7: ='AW28'!F66 -> 31 | Z7: ='AW29'!F77 -> 43 | AA7: ='AW31'!F24 -> 16 | AB7: ='AW32'!F83 -> 44
B8: SMP | C8: =AW1_!F166 -> 34 | D8: ='AW3'!G171 -> 131 | E8: ='AW4'!F92 -> 16 | G8: =SUM(C8:E8) -> 181 | I8: SMP | K8: ='AW7'!F24 -> 11 | O8: ='AW13'!F28 -> 18 | P8: ='AW14'!F84 -> 23 | Q8: ='AW15'!F100 -> 26 | R8: ='AW16'!F81 -> 26 | Y8: ='AW28'!F67 -> 22 | Z8: ='AW29'!F78 -> 22 | AA8: ='AW31'!F25 -> 3 | AB8: ='AW32'!F84 -> 29
B9: SMA | C9: =AW1_!F167 -> 18 | D9: ='AW3'!G172 -> 37 | E9: ='AW4'!F93 -> 5 | G9: =SUM(C9:E9) -> 60 | I9: SMA | K9: ='AW7'!F25 -> 4 | O9: ='AW13'!F29 -> 7 | P9: ='AW14'!F85 -> 5 | Q9: ='AW15'!F101 -> 8 | R9: ='AW16'!F82 -> 2 | Y9: ='AW28'!F68 -> 6 | Z9: ='AW29'!F79 -> 9 | AA9: ='AW31'!F26 -> 2 | AB9: ='AW32'!F85 -> 7
B11: TOTAL/CABANG | C11: =sum(C4:C9) -> 159 | D11: =sum(D4:D9) -> 168 | E11: =sum(E4:E9) -> 88 | G11: =SUM(C11:E11) -> 415 | I11: TOTAL/CABANG | K11: =sum(K4:K9) -> 20 | M11: =sum(M4:M9) -> 0 | N11: =sum(N4:N9) -> 0 | O11: =sum(O4:O9) -> 25 | P11: =sum(P4:P9) -> 80 | Q11: =sum(Q4:Q9) -> 96 | S11: =sum(S4:S9) -> 0 | T11: =sum(T4:T9) -> 0 | U11: =sum(U4:U9) -> 0 | V11: =sum(V4:V9) -> 0 | W11: =sum(W4:W9) -> 0 | X11: =sum(X4:X9) -> 0 | Y11: =sum(Y4:Y9) -> 59 | Z11: =sum(Z4:Z9) -> 74 | ... AB11: =sum(AB4:AB9) -> 80
B12: TOTAL | C12: =SUM(C11:E11) -> 415 | I12: TOTAL | K12: =sum(K11:U11) -> 221
C14: SABTU, 19 SEPT 2026
C15: AHAD, 20 SEPT 2026

Sheet AW1_
A1: NO | B1: NAMA LENGKAP | C1: EMAIL | D1: NO KONTAK YANG BISA DIHUB (gunakan 62...) | E1: JENIS KELAMIN | F1: JENJANG | G1: PROGRAM (BOARDING/FULLDAY) | H1: KELAS | I1: TYPE | J1: PEMINATAN
A2: 1 | B2: ZIANKA AYNA BALWISA | C2: bayu.larasandi@gmail.com | D2: 6281930388890 | E2: Perempuan | F2: SD | G2: Fullday | H2: 1 | J2: INTER
A3: 2 | B3: RAIHAN FIRLY ABDILLAH | C3: firlyabdillah@outlook.com | D3: 628129888888 | E3: Laki-laki | F3: SD | G3: Fullday | H3: 1 | J3: INTER
A4: 3 | B4: SHANUM BINAR ALMAHYRA | C4: detikadina@gmail.com | D4: 628174866165 | E4: Perempuan | F4: SD | G4: Fullday | H4: 1 | J4: INTER
A5: 4 | B5: REZVAN YUSUF NAYAZKAPUTRA | C5: tyaskusumarayisiwi@gmail.com | D5: 6281228431131 | E5: Laki-laki | F5: SD | G5: Fullday | H5: 1 | J5: INTER
A6: 5 | B6: SABIRA ALMAHYRA HARFIAN | C6: nerissaines@gmail.com | D6: 6285773552375 | E6: Perempuan | F6: TK-A | G6: Fullday | H6: TK-A | J6: INTER
A7: 6 | B7: NADINE AISYAH ZHAFARINA | C7: annesalatifa1@gmail.com | D7: 6282386389392 | E7: Perempuan | F7: TK-A | G7: Fullday | H7: TK-A | J7: INTER
A8: 7 | B8: NAZHIFAH IZZATI HUWAIDAH | C8: suci.zainur@gmail.com | D8: 628174835700 | E8: Perempuan | F8: SMP | G8: Fullday | H8: 7 | J8: MQ
A9: 8 | B9: DINANDIRA ASMARA RIMELDIAN | C9: radiangilang18@yahoo.com | D9: 6282218180793 | E9: Perempuan | F9: TK-A | G9: Fullday | H9: TK-A | J9: INTER
A10: 9 | B10: AMMAR AASHIF SALAM | C10: yogani.saktya@gmail.com | D10: 6285726499000 | E10: Laki-laki | F10: SD | G10: Fullday | H10: 1 | J10: INTER
A11: 10 | B11: SHEZA ADZKIYA NAJMA HARIANTO | C11: hariantosugeng947@gmail.com | D11: 628118006694 | E11: Perempuan | F11: SMP | G11: Fullday | H11: 7 | J11: AE
A12: 11 | B12: MUHAMMAD EMIRSYAH AL RASYID PRATAMA | C12: utarieka19@gmail.com | D12: 6281317809951 | E12: Laki-laki | F12: SD | G12: Fullday | H12: 1 | J12: INTER
A13: 12 | B13: MUHAMMAD GUINANDRA KHALID ERDOGAN | C13: jimmysatriop@gmail.com | D13: 6282112361774 | E13: Laki-laki | F13: SD | G13: Fullday | H13: 1 | J13: INTER
A14: 13 | B14: SYAKIRA ALYA SHAZIVA | C14: millatinaarimi@gmail.com | D14: 6281586824977 | E14: Perempuan | F14: SD | G14: Fullday | H14: 1 | J14: INTER
A15: 14 | B15: NABILA ARDYA PUTRI NUGROHO | C15: lidyatrioctarina@gmail.com | D15: 6281296577508 | E15: Perempuan | F15: SMP | G15: Fullday | H15: 7 | J15: AE
A16: 15 | B16: SHAREENA RIZKY TUAH | C16: d.shareena13@gmail.com | D16: 62281385570737 | E16: Perempuan | F16: SMA | G16: Boarding | H16: 10 | J16: MQ
A17: 16 | B17: ALI ARSYAD | C17: rozy4136@gmail.com | D17: 6285220808050 | E17: Laki-laki | F17: TK-A | G17: Fullday | H17: TK-A | J17: INTER
A18: 17 | B18: AMBERLYN ADIANA SHAFIYYA | C18: adi.suwito@gmail.com | D18: 628111091520 | E18: Perempuan | F18: SMP | G18: Fullday | H18: 7 | J18: MQ
A19: 18 | B19: FATIMAH RENJANA HABIBAH | C19: faathiraa09@gmail.com | D19: 6285717001990 | E19: Perempuan | F19: PG | G19: Fullday | H19: PG | J19: INTER
A20: 19 | B20: LOVELYRA FATHYA SANTOSO | C20: ika.sunday@gmail.com | D20: 626281311230007 | E20: Perempuan | F20: SMA | G20: Boarding | H20: 10 | J20: DI
A21: 20 | B21: AKASYA ANINDIRA GHIFARI | C21: baskaraedith@gmail.com | D21: 6282124922073 | E21: Perempuan | F21: SD | G21: Fullday | H21: 1 | J21: INTER
A22: 21 | B22: OTELLO RAZAQ KAFMAIDI | C22: rnsantosa@gmail.com | D22: 628151619698 | E22: Laki-laki | F22: TK-B | G22: Fullday | H22: TK-B | J22: INTER
A23: 22 | B23: MUHAMMAD ALFATIH | C23: nacha@nasteq.sg | D23: 6287815279909 | E23: Laki-laki | F23: TK-B | G23: Fullday | H23: TK-B | J23: INTER
A24: 23 | B24: FATIMAH KHAIRUNNISA MAYENDRA | C24: ratnanurayu8@gmail.com | D24: 6281266400705 | E24: Perempuan | F24: TK-B | G24: Fullday | H24: TK-B | J24: INTER
A25: 24 | B25: SYAZANI MAHASIN LAIQA | C25: gabyamandaviola@gmail.com | D25: 6282299702660 | E25: Perempuan | F25: TK-A | G25: Fullday | H25: TK-A | J25: INTER
A26: 25 | B26: MUHAMMAD UMAR SYAFIQ | C26: syafinannajah@gmail.com | D26: 6285710345962 | E26: Laki-laki | F26: SD | G26: Fullday | H26: 1 | J26: MQ
A27: 26 | B27: HAURA HUMAIRA NURAZWAR | C27: izam.nurazwar@gmail.com | D27: 628111981895 | E27: Perempuan | F27: SD | G27: Fullday | H27: 1 | J27: INTER
A28: 27 | B28: NAYYARA ALMEERA WIJAYA | C28: rizkifitririrlulia@gmail.com | D28: 6281382281028 | E28: Perempuan | F28: SMP | G28: Fullday | H28: 7 | J28: AE
A29: 28 | B29: ALGHANI AUSY FIRDAUS | C29: sitiaghniaafifah@gmail.com | D29: 628997672383 | E29: Laki-laki | F29: SD | G29: Fullday | H29: 1 | J29: INTER
A30: 29 | B30: MUHAMMAD IZZAN ALFATIH | C30: debykurnia21@gmail.com | D30: 6281324651905 | E30: Laki-laki | F30: SD | G30: Fullday | H30: 1 | J30: INTER
A31: 30 | B31: ZADA BARIK SALAM | C31: tintakalamillah@gmail.con | D31: 6281385333373 | E31: Laki-laki | F31: SD | G31: Fullday | H31: 1 | J31: INTER
A32: 31 | B32: GHAFIQI ETIZAAZ SYAUQI | C32: silvia.rhmwt26@gmail.com | D32: 6281213707092 | E32: Laki-laki | F32: SD | G32: Fullday | H32: 1 | J32: INTER
A33: 32 | B33: KEISHA SAIRA AFSHEENA | C33: indahmel8928@gmail.com | D33: 6281288035400 | E33: Perempuan | F33: SMP | G33: Boarding | H33: 7 | J33: AE
A34: 33 | B34: MARYAM QIYYAMA JAMEELA | C34: dattyaprl10@gmail.com | D34: 6281317710329 | E34: Perempuan | F34: SD | G34: Fullday | H34: 1 | J34: INTER
A35: 34 | B35: KEIRA LAVANYA FADHILLAH | C35: hanief64@gmail.com | D35: 6285729481960 | E35: Perempuan | F35: SMP | G35: Fullday | H35: 7 | J35: MQ
A36: 35 | B36: NADYA AYUNDA PUTRI | C36: sriyulianie999@gmail.com | D36: 6282166678080 | E36: Perempuan | F36: SMP | G36: Boarding | H36: 7 | J36: MQ
A37: 36 | B37: MIKHAYLA FAKHIRA RAMADHANI ANDREAS | C37: dessyyenriany2610@gmail.com | D37: 6282173151505 | E37: Perempuan | F37: SMP | G37: Boarding | H37: 7 | J37: AE
... A48: 47 | B48: FILDZAH ALFATYAH ZUHRI | C48: defeduyasih@gmail.com | D48: 6285261302929 | E48: Perempuan | F48: SMP | G48: Fullday | H48: 7 | J48: AE
A49: 48 | B49: MUHAMMAD UWAIS | C49: rahmayunita727@gmail.com | D49: 6281362215394 | E49: Laki-laki | F49: TK-A | G49: Fullday | H49: TK-A | J49: INTER
A50: 49 | B50: FATIMAH AZ ZAHIDAH | C50: alifahso77@gmail.com | D50: 6282175952335 | E50: Perempuan | F50: SMP | G50: Fullday | H50: 7 | J50: MQ
...

Sheet AW2_
A1: NO | B1: NAMA LENGKAP | C1: EMAIL | D1: NO KONTAK YANG BISA DIHUB (gunakan 62...) | E1: JENIS KELAMIN | F1: JENJANG | G1: PROGRAM (BOARDING/FULLDAY) | H1: KELAS | I1: TYPE | J1: PEMINATAN
A2: 1
A3: 2
A4: 3
A5: 4
A6: 5
A7: 6
A8: 7
A9: 8
A10: 9
A11: 10
A12: 11
A13: 12
... A123: 122

Sheet AW3
A1: NO | B1: NAMA LENGKAP | C1: EMAIL | D1: NO KONTAK YANG BISA DIHUB (gunakan 62...) | E1: JENIS KELAMIN | F1: JENJANG | G1: PROGRAM (BOARDING/FULLDAY) | H1: KELAS | I1: TYPE | J1: PEMINATAN
A2: 1 | B2: AIZAR DAVIAN KAYYISI | C2: vicka.rostanti@gmail.com | D2: 6281299073727 | E2: LAKI-LAKI | F2: SMP | G2: FULLDAY | H2: 7 | J2: AE
A3: 2 | B3: FADHIL ALIY FIDDIN | C3: erwinsyanti@gmail.com | D3: 628119590277 | E3: LAKI-LAKI | F3: SMP | G3: BOARDING | H3: 7 | J3: AE
A4: 3 | B4: FAEYZA JUNO TSAFIQ KUSDIANTO | C4: chef_anto@yahoo.com | D4: 6282123228846 | E4: LAKI-LAKI | F4: SMP | G4: BOARDING | H4: 7 | J4: AE
A5: 4 | B5: AZZAMY AL KARIIM YUNIAL | C5: ocharaysah@gmail.com | D5: 6281219236955 | E5: LAKI-LAKI | F5: SMP | G5: FULLDAY | H5: 7 | J5: AE
A6: 5 | B6: SIENAAN SYAHMI RAIQELPAMA | C6: sofa.nurussausan@gmail.com | D6: 6282114246381 | E6: LAKI-LAKI | F6: SMP | G6: BOARDING | H6: 7 | J6: AE
A7: 6 | B7: REYNAND DZAKI AZKA | C7: wati.erna1978@gmail.com | D7: 6281315442527 | E7: LAKI-LAKI | F7: SMP | G7: FULLDAY | H7: 7 | J7: AE
A8: 7 | B8: USAMAH JALALUDIN IQBAL | C8: natayaindah.permatasari@gmail.com | D8: 6281210003663 | E8: LAKI-LAKI | F8: SMP | G8: BOARDING | H8: 7 | J8: AE
A9: 8 | B9: ARKAN ATMA SYAHIRAN | C9: itcha.caropeboka@gmail.com | D9: 6281272022784 | E9: LAKI-LAKI | F9: SMA | G9: BOARDING | H9: 10 | J9: ME IPA
A10: 9 | B10: HAFIZH AZIZUL HAKIM | C10: muftie.hakim@gmail.com | D10: 6285216314423 | E10: LAKI-LAKI | F10: SMP | G10: BOARDING | H10: 7 | J10: AE
A11: 10 | B11: MUHAMMAD ADRIZKY | C11: syarifahdewifitriany@gmail.com | D11: 6285264033330 | E11: LAKI-LAKI | F11: SMA | G11: BOARDING | H11: 10 | J11: DI IPA
A12: 11 | B12: KEN MARUTA RASYADI | C12: sawitriwening@gmail.com | D12: 6281291088048 | E12: LAKI-LAKI | F12: SMP | G12: FULLDAY | H12: 7 | J12: AE
A13: 12 | B13: TUANKU FAITH RASYID | C13: yolen.perdana89@gmail.com | D13: 6281321509820 | E13: LAKI-LAKI | F13: SMP | G13: FULLDAY | H13: 7 | J13: AE
... A169: 168 | B169: AKHTAR AHNAF ARRIFY | C169: amasniari@gmail.com | D169: 6281321343866 | E169: LAKI-LAKI | F169: SMP | G169: BOARDING | H169: 7 | J169: AE
F171: SMP | G171: =countif($F$2:$F$169,F171) -> 131
F172: SMA | G172: =countif($F$2:$F$169,F172) -> 37
G173: =SUM(G171:G172) -> 168

Sheet AW4
A1: NO | B1: NAMA LENGKAP | C1: EMAIL | D1: NO KONTAK YANG BISA DIHUB (gunakan 62...) | E1: JENIS KELAMIN | F1: JENJANG | G1: PROGRAM (BOARDING/FULLDAY) | H1: KELAS | I1: TYPE | J1: PEMINATAN
A2: 1 | B2: MUHAMMAD ZYNATA AZ ZUBAIR ALINGGA | C2: alif.jannati@gmail.com | D2: 6281259520128 | E2: Laki-laki | F2: SD | G2: FULLDAY | H2: 1 | J2: International
A3: 2 | B3: MARYAM ALMAHYRA HARMINTO | C3: try.harminto@gmail.com | D3: 6281314614641 | E3: Perempuan | F3: SD | G3: FULLDAY | H3: 1 | J3: International
A4: 3 | B4: KHADIJAH ATIRA SAFINA | C4: hartanti.lusi@gmail.com | D4: 6281905026127 | E4: Perempuan | F4: SD | G4: FULLDAY | H4: 1 | J4: International
A5: 4 | B5: RAIHANA VALERIE ASSYAMSI | C5: irfani.has.i@gmail.com | D5: 6281995091909 | E5: Perempuan | F5: SD | G5: FULLDAY | H5: 1 | J5: International
A6: 5 | B6: DAHAYU NIRWASITA IBRAHIM | C6: rnazisha@gmail.com | D6: 6281219258492 | E6: Perempuan | F6: SD | G6: FULLDAY | H6: 1 | J6: International
A7: 6 | B7: TSABBITA QOLBI YUMNA IRAWAN | C7: restiseptia@gmail.com | D7: 6281254100666 | E7: Perempuan | F7: SD | G7: FULLDAY | H7: 4 | J7: International
A8: 7 | B8: GYAN RAJENDRA SAFAR | C8: dhian.komala@rocketmail.com | D8: 6281373015487 | E8: Laki-laki | F8: SD | G8: FULLDAY | H8: 1 | J8: International
A9: 8 | B9: MALIKA ZERINA AIASHAFEYA ROSALDY | C9: rosmeiliadradjat@gmail.com | D9: 6281288735796 | E9: Perempuan | F9: SD | G9: FULLDAY | H9: 1 | J9: International
A10: 9 | B10: FAQIH SHAWQI ABDULLAH IRAWAN | C10: restiseptia@gmail.com | D10: 6289530004004 | E10: Laki-laki | F10: SD | G10: FULLDAY | H10: 1 | J10: MQ
A11: 10 | B11: INARA MITSAQAN GHALIDZA IRAWAN | C11: restiseptia@gmail.com | D11: 6281347471576 | E11: Perempuan | F11: SMP | G11: FULLDAY | H11: 7 | J11: MQ
A12: 11 | B12: RAFAYZA AZHAM SAFARAZ | C12: kanialaksono@gmail.com | D12: 628118208411 | E12: Laki-laki | F12: SD | G12: FULLDAY | H12: 4 | J12: International
A13: 12 | B13: MUSA ABDUSSALAAM JABBAAR | C13: apriy4nt0@gmail.com | D13: 6281384852424 | E13: Laki-laki | F13: SMA | G13: FULLDAY | H13: 10 | J13: DI-IPA
... A89: 88 | B89: SUMAYYAH PUTRI ALANA | C89: wulandariayualifah@gmail.com | D89: 6282210506882 | E89: Perempuan | F89: SD | G89: FULLDAY | H89: 1 | J89: International
E91: SD | F91: =COUNTIF($F$2:$F$89,E91) -> 67
E92: SMP | F92: =COUNTIF($F$2:$F$89,E92) -> 16
E93: SMA | F93: =COUNTIF($F$2:$F$89,E93) -> 5
F94: =SUM(F91:F93) -> 88

Sheet AW5
A1: NO | B1: NAMA LENGKAP | C1: EMAIL | D1: NO KONTAK YANG BISA DIHUB (gunakan 62...) | E1: JENIS KELAMIN | F1: JENJANG | G1: PROGRAM (BOARDING/FULLDAY) | H1: KELAS | I1: TYPE | J1: PEMINATAN
A2: 1 | B2: Amahiro Syah Mishary Akbar | C2: vina@naufal-akbar.com | D2: 081905509099 | E2: Laki-laki | F2: SD | G2: FULDAY | H2: 1 | I2: A | J2: INTER
A3: 2 | B3: Gilzah El Feiyaz | C3: waisya.hidayat@pttimah.co.id | D3: 082136673959 | E3: Perempuan | F3: SD | G3: FULDAY | H3: 1 | I3: A | J3: INTER
A4: 3 | B4: Maisaroh Aflaha | C4: solemankondakh@gmail.com | D4: 085321223031 | E4: Perempuan | F4: SD | G4: FULDAY | H4: 1 | I4: A | J4: INTER
A5: 4 | B5: Charnelis Zea Zahra Almayra | C5: ratnasarid2wi19@gmail.com | D5: 081280800509 | E5: Perempuan | F5: SD | G5: FULDAY | H5: 1 | I5: A | J5: INTER
A6: 5 | B6: Muhammad Raja Al Fatih | C6: wahyusepti.em@gmail.com | D6: 082170488349 | E6: Laki-laki | F6: SD | G6: FULDAY | H6: 1 | I6: A | J6: INTER
A7: 6 | B7: Shafiyyah Ashila Kamila | C7: mellisa.aslim@gmail.com | D7: 08128621616 | E7: Perempuan | F7: SD | G7: FULDAY | H7: 1 | I7: A | J7: INTER
A8: 7 | B8: Shaquil Dzakiandra Atharauf | C8: novita.riri96@gmail.com | D8: 082130507766 | E8: Laki-laki | F8: SD | G8: FULDAY | H8: 1 | I8: A | J8: INTER
A9: 8 | B9: Khalid Karel Emran | C9: liapermatasari47@gmail.com | D9: 081808125782 | E9: Laki-laki | F9: SD | G9: FULDAY | H9: 1 | I9: A | J9: INTER
A10: 9 | B10: DANIYAL RAQILA SHAHARYAR | C10: khaudly@gmail.com | D10: 081284928764 | E10: Laki-laki | F10: SD | G10: FULDAY | H10: 1 | I10: A | J10: INTER
A11: 10 | B11: Atri Widyawati Khoiriyah | C11: tri.w.nugraheni@gmail.com | D11: 085225487022 | E11: Perempuan | F11: SD | G11: FULDAY | H11: 1 | I11: A | J11: INTER
A12: 11 | B12: Muhammad Rasyad Alzaidan | C12: charmania19@gmail.com | D12: 081381436644 | E12: Laki-laki | F12: SD | G12: FULDAY | H12: 1 | I12: A | J12: INTER
A13: 12 | B13: Harun Khaled Hamdun | C13: alhamdoon@gmail.com | D13: 08569000770 | E13: Laki-laki | F13: SD | G13: FULDAY | H13: 1 | I13: A | J13: INTER
... A27: 26 | B27: SHAFURA HADEEQA | C27: aawaliah11@gmail.com | D27: 081284482588 | E27: Perempuan | F27: SD | G27: FULDAY | H27: 1 | I27: A | J27: INTER
E31: SD | F31: =COUNTIF($F$2:$F$27,E31) -> 26

Sheet AW7
A1: NO | B1: NAMA LENGKAP | C1: EMAIL | D1: NO KONTAK YANG BISA DIHUB (gunakan 62...) | E1: JENIS KELAMIN | F1: JENJANG | G1: PROGRAM (BOARDING/FULLDAY) | H1: KELAS | I1: TYPE | J1: PEMINATAN
A2: 1 | B2: AZMI AMANI | C2: auliafitrifatimah@gmail.com | D2: 087888696432 | E2: Laki-laki | F2: SMA | G2: Boarding | H2: 10 | J2: ME
A3: 2 | B3: IHSAN AMANI | C3: auliafitrifatimah@gmail.com | D3: 087888696432 | E3: Laki-laki | F3: SMP | G3: Boarding | H3: 7 | J3: AE
A4: 3 | B4: AZKA HAFIZH ARRASYID | C4: ciptoito@gmail.com | D4: 08979428864 | E4: Laki-laki | F4: SMP | G4: Boarding | H4: 7 | J4: AE
A5: 4 | B5: FAHMI ATHALLA ARKAN | C5: wahyudiekop@yahoo.com | D5: 085695551876 | E5: Laki-laki | F5: SMP | G5: Fullday | H5: 7 | J5: AE
A6: 5 | B6: MARYAM | C6: najwasiagian7@gmail.com | D6: 087808104031 | E6: Perempuan | F6: SD | G6: Fullday | H6: 1 | J6: INTER
A7: 6 | B7: SADDAM AL-HAFIZ KIRANA | C7: yipikai.rieq@gmail.com | D7: 087771733378 | E7: Laki-laki | F7: SMP | G7: Fullday | H7: 7 | J7: AE
A8: 7 | B8: DAVIN SEBASTIAN | C8: nurahayu7681@gmail.com | D8: 081385553311 | E8: Laki-laki | F8: SMP | G8: Fullday | H8: 7 | J8: AE
A9: 8 | B9: FATIMAH CAHAYA JATI NINGRAT | C9: agustinadesti@gmail.com | D9: 081311697728 | E9: Perempuan | F9: SD | G9: Fullday | H9: 1 | J9: INTER
A10: 9 | B10: MUHAMMAD KHYKO JENAR | C10: birhaO2hexawater@gmail.com | D10: 081911298899 | E10: Laki-laki | F10: SMA | G10: Fullday | H10: 10 | J10: DI
A11: 10 | B11: FIKRA ALI MUYASSAR | C11: safranicordoba@gmail.com | D11: 08567693180 | E11: Laki-laki | F11: SMA | G11: Boarding | H11: 10 | J11: DI
A12: 11 | B12: ELFATHAN DAVIS ITALYONO | C12: italyono.c@gmail.com | D12: 081318552025 | E12: Laki-laki | F12: SMP | G12: Boarding | H12: 7 | J12: AE
A13: 12 | B13: HAMZAH ABDUL JABBAR | C13: syahidahazkia99@gmail.com | D13: 087878027418 | E13: Laki-laki | F13: SD | G13: Fullday | H13: 1 | J13: INTER
... A21: 20 | B21: FARAZ FADHILAH RAHMAN | C21: rojalisalim@gmail.com | D21: 085946555317 | E21: Laki-laki | F21: SMP | G21: Boarding | H21: 7 | J21: MQ
E23: SD | F23: =COUNTIF($F$2:$F$21,E23) -> 5
E24: SMP | F24: =COUNTIF($F$2:$F$21,E24) -> 11
E25: SMA | F25: =COUNTIF($F$2:$F$21,E25) -> 4
F26: =SUM(F23:F25) -> 20

Sheet AW8
A1: NO | B1: NAMA LENGKAP | C1: EMAIL | D1: NO KONTAK YANG BISA DIHUB (gunakan 62...) | E1: JENIS KELAMIN | F1: JENJANG | G1: PROGRAM (BOARDING/FULLDAY) | H1: KELAS | I1: TYPE | J1: PEMINATAN
A2: 1
A3: 2
A4: 3
A5: 4
A6: 5
A7: 6
A8: 7
A9: 8
A10: 9
A11: 10
A12: 11
A13: 12
A14: 13

Sheet AW10
A1: NO | B1: NAMA LENGKAP | C1: EMAIL | D1: NO KONTAK YANG BISA DIHUB (gunakan 62...) | E1: JENIS KELAMIN | F1: JENJANG | G1: PROGRAM (BOARDING/FULLDAY) | H1: KELAS | I1: TYPE | J1: PEMINATAN
A2: 1
A3: 2
A4: 3
A5: 4
A6: 5
A7: 6
A8: 7
A9: 8
A10: 9
A11: 10
A12: 11
A13: 12
A14: 13

Sheet AW11
A1: NO | B1: NAMA LENGKAP | C1: EMAIL | D1: NO KONTAK YANG BISA DIHUB (gunakan 62...) | E1: JENIS KELAMIN | F1: JENJANG | G1: PROGRAM (BOARDING/FULLDAY) | H1: KELAS | I1: TYPE | J1: PEMINATAN
A2: 1 | B2: Medina Aisyah Tamarifa | C2: trini.indrati@gmail.com | D2: 0878-8605-6860 | E2: Perempuan | F2: SMA | G2: FULLDAY | H2: 11 | J2: AE
A3: 2 | B3: Avicenna Maliki Raushan Sahir | C3: syarifah.c.amaliya@gmail.com | D3: 81315466181 | E3: Laki-laki | F3: SMA | G3: FULLDAY | H3: 10 | J3: AE
A4: 3 | B4: Naysilla Sheza Adreena | C4: papiarsha@gmail.com | D4: 81326769393 | E4: Perempuan | F4: SMP | G4: FULLDAY | H4: 7 | J4: AE
A5: 4 | B5: Nadhifa Salsabila Aulia | C5: mg.nurmalasari@gmail.com | D5: 81213441902 | E5: Perempuan | F5: SMP | G5: FULLDAY | H5: 7 | J5: AE
A6: 5
A7: 6
A8: 7
A9: 8
A10: 9
A11: 10
A12: 11
A13: 12
A14: 13

Sheet AW12
A1: NO | B1: NAMA LENGKAP | C1: EMAIL | D1: NO KONTAK YANG BISA DIHUB (gunakan 62...) | E1: JENIS KELAMIN | F1: JENJANG | G1: PROGRAM (BOARDING/FULLDAY) | H1: KELAS | I1: TYPE | J1: PEMINATAN
A2: 1
A3: 2
A4: 3
A5: 4
A6: 5
A7: 6
A8: 7
A9: 8
A10: 9
A11: 10
A12: 11
A13: 12
A14: 13

Sheet AW13
A1: NO | B1: NAMA LENGKAP | C1: EMAIL | D1: NO KONTAK YANG BISA DIHUB (gunakan 62...) | E1: JENIS KELAMIN | F1: JENJANG | G1: PROGRAM (BOARDING/FULLDAY) | H1: KELAS | I1: TYPE | J1: PEMINATAN
A2: 1 | B2: AISYAH ZULFAH MUFLIHAH | C2: nisakchoirin@gmail.com | D2: 6282113584707 | E2: Perempuan | F2: SMP | G2: BOARDING | H2: =IF(F2="SMP",7,IF(F2="SMA",10,"")) -> 7 | I2: MQ-ME
A3: 2 | B3: AMEERA SHEIKHA MAJEEDAH | C3: agung.platg@gmail.com | D3: 6283890349834 | E3: Perempuan | F3: SMP | G3: BOARDING | H3: =IF(F3="SMP",7,IF(F3="SMA",10,"")) -> 7 | I3: MQ-ME
A4: 3 | B4: KALILA RAMADHANI PRASADHA | C4: k.kusumawardani@gmail.com | D4: 628562004115 | E4: Perempuan | F4: SMP | G4: BOARDING | H4: =IF(F4="SMP",7,IF(F4="SMA",10,"")) -> 7 | I4: MQ-ME
A5: 4 | B5: MYSHA SHANUM ENDREVA | C5: angginoviani001@gmail.com | D5: 628112224572 | E5: Perempuan | F5: SMP | G5: BOARDING | H5: =IF(F5="SMP",7,IF(F5="SMA",10,"")) -> 7 | I5: MQ-ME
A6: 5 | B6: FAIHA ASHA ALMADINA | C6: juamal.wil7@gmail.com | D6: 6285345905959 | E6: Perempuan | F6: SMP | G6: BOARDING | H6: =IF(F6="SMP",7,IF(F6="SMA",10,"")) -> 7 | I6: MQ-ME
A7: 6 | B7: AISYAH | C7: akang.galih@gmail.com | D7: 6281318071801 | E7: Perempuan | F7: SMP | G7: BOARDING | H7: =IF(F7="SMP",7,IF(F7="SMA",10,"")) -> 7 | I7: MQ-ME
A8: 7 | B8: KHAULAH DZAKIYYAH ISKANDAR | C8: ellisapmp22@gmail.com | D8: 628567438667 | E8: Perempuan | F8: SMP | G8: BOARDING | H8: =IF(F8="SMP",7,IF(F8="SMA",10,"")) -> 7 | I8: MQ-ME
A9: 8 | B9: KINANDYA ZAHIRRA SHANUM | C9: kb.hartanto@gmail.com | D9: 6281290709744 | E9: Perempuan | F9: SMP | G9: BOARDING | H9: =IF(F9="SMP",7,IF(F9="SMA",10,"")) -> 7 | I9: MQ-ME
A10: 9 | B10: ALESHA KHAIRA WILDA | C10: asihnovianti01@gmail.com | D10: 6281214985609 | E10: Perempuan | F10: SMP | G10: BOARDING | H10: =IF(F10="SMP",7,IF(F10="SMA",10,"")) -> 7 | I10: MQ-ME
A11: 10 | B11: SYAFIYAH NUR FAIDAH | C11: metri.spgdt119@gmail.com | D11: 6287773890490 | E11: Perempuan | F11: SMP | G11: BOARDING | H11: =IF(F11="SMP",7,IF(F11="SMA",10,"")) -> 7 | I11: MQ-ME
A12: 11 | B12: NADHIFA CAHYA KAMILA | C12: maya.triansyah@gmail.com | D12: 6285880523759 | E12: Perempuan | F12: SMP | G12: BOARDING | H12: =IF(F12="SMP",7,IF(F12="SMA",10,"")) -> 7 | I12: MQ-ME
A13: 12 | B13: SHYVA ANINDYA HARIYADI | C13: hariyadi_2906@yahoo.com | D13: 6281329392355 | E13: Perempuan | F13: SMP | G13: BOARDING | H13: =IF(F13="SMP",7,IF(F13="SMA",10,"")) -> 7 | I13: MQ-ME
A14: 13 | B14: AISYA IRINA RIFDA | C14: cumplunxs@gmail.com | D14: 628157775187 | E14: Perempuan | F14: SMA | G14: BOARDING | H14: =IF(F14="SMP",7,IF(F14="SMA",10,"")) -> 10 | I14: MQ-ME | J14: IPA
A15: 14 | B15: NAAILAH FAAIZAH | C15: uutjefry@gmail.com | D15: 6285368649995 | E15: Perempuan | F15: SMA | G15: BOARDING | H15: =IF(F15="SMP",7,IF(F15="SMA",10,"")) -> 10 | I15: MQ-ME | J15: IPA
A16: 15 | B16: YUMNA | C16: mayasari.evie@gmail.com | D16: 6282127397497 | E16: Perempuan | F16: SMP | G16: BOARDING | H16: =IF(F16="SMP",7,IF(F16="SMA",10,"")) -> 7 | I16: MQ-ME
A17: 16 | B17: ZAINAB T. BALADRAF | C17: nafilabaladraf90@gmail.com | D17: 628114310695 | E17: Perempuan | F17: SMA | G17: BOARDING | H17: =IF(F17="SMP",7,IF(F17="SMA",10,"")) -> 10 | I17: MQ-ME | J17: IPA
A18: 17 | B18: MANAL G BALADRAF | C18: fathiabaladaraf80@gmail.com | D18: 6281341299551 | E18: Perempuan | F18: SMA | G18: BOARDING | H18: =IF(F18="SMP",7,IF(F18="SMA",10,"")) -> 10 | I18: MQ-ME | J18: IPA
A19: 18 | B19: SYEIKHAH UZMA AQILAH | C19: auditya.dinda@gmail.com | D19: 6285884735320 | E19: Perempuan | F19: SMP | G19: BOARDING | H19: =IF(F19="SMP",7,IF(F19="SMA",10,"")) -> 7 | I19: MQ-ME
A20: 19 | B20: KAYYISAH ADZKIA SUFI RACHMAN | C20: sufitrid@gmail.com | D20: 6281212652653 | E20: Perempuan | F20: SMP | G20: BOARDING | H20: =IF(F20="SMP",7,IF(F20="SMA",10,"")) -> 7 | I20: MQ-ME
A21: 20 | B21: MEDINA AZZAQUEERA WIBOWO | C21: rifka4188@gmail.com | D21: 6281318168500 | E21: Perempuan | F21: SMP | G21: BOARDING | H21: =IF(F21="SMP",7,IF(F21="SMA",10,"")) -> 7 | I21: MQ-ME
A22: 21 | B22: AISHA MUGHNY SHALIHA AIMAN | C22: adeiman.krisdiana02@gmail.com | D22: 6285774912463 | E22: Perempuan | F22: SMA | G22: BOARDING | H22: =IF(F22="SMP",7,IF(F22="SMA",10,"")) -> 10 | I22: MQ-ME | J22: IPA
A23: 22 | B23: FAIZA | C23: yantokaribo21@gmail.com | D23: 6282291299228 | E23: Perempuan | F23: SMA | G23: BOARDING | H23: =IF(F23="SMP",7,IF(F23="SMA",10,"")) -> 10 | I23: MQ-ME | J23: IPS
A24: 23 | B24: AZIZAH NUR AFIAH | C24: erny.masiha@gmail.com | D24: 62811407220 | E24: Perempuan | F24: SMP | G24: BOARDING | H24: =IF(F24="SMP",7,IF(F24="SMA",10,"")) -> 7 | I24: MQ-ME
A25: 24 | B25: FATHIYA ALIYYA ZULKIFLY | C25: zulkifly.06@gmail.com | D25: 6281373783736 | E25: Perempuan | F25: SMP | G25: BOARDING | H25: =IF(F25="SMP",7,IF(F25="SMA",10,"")) -> 7 | I25: MQ-ME
A26: 25 | B26: FARRAS KAMILA ZULKIFLY | C26: zulkifly.06@gmail.com | D26: 6281373783736 | E26: Perempuan | F26: SMA | G26: BOARDING | H26: =IF(F26="SMP",7,IF(F26="SMA",10,"")) -> 10 | I26: MQ-ME | J26: IPS
E28: SMP | F28: =COUNTIF($F$2:$F$26,E28) -> 18
E29: SMA | F29: =COUNTIF($F$2:$F$26,E29) -> 7
F30: =SUM(F28:F29) -> 25

Sheet AW14
A1: NO | B1: NAMA LENGKAP | C1: EMAIL | D1: NO KONTAK YANG BISA DIHUB (gunakan 62...) | E1: JENIS KELAMIN | F1: JENJANG | G1: PROGRAM (BOARDING/FULLDAY) | H1: KELAS | I1: TYPE | J1: PEMINATAN
A2: 1 | B2: Haykal Danu Putra | C2: nurcholis.hh@gmail.com | D2: 6281513353370 | E2: Laki-laki | F2: SMA | G2: FULLDAY | H2: 10 | I2: DI | J2: IPS
A3: 2 | B3: Qalesyalim Hazima Arsyad | C3: rimanurul33@gmail.com | D3: 6281213307465 | E3: Laki-laki | F3: SMA | G3: FULLDAY | H3: 10 | I3: DI | J3: IPA
A4: 3 | B4: Maryam Alesya Azzahrawain | C4: miftahna18@gmail.com | D4: 62817180591 | E4: Perempuan | F4: SD | G4: FULLDAY | H4: 3 | I4: INTER
A5: 4 | B5: Khadijah Falisha Azzahrawain | C5: miftahna18@gmail.com | D5: 62817180591 | E5: Perempuan | F5: SD | G5: FULLDAY | H5: 1 | I5: INTER
A6: 5 | B6: Alkemi Ali Musa | C6: yukinagarani@gmail.com | D6: 6281282982473 | E6: Laki-laki | F6: SMP | G6: FULLDAY | H6: 7 | I6: AE
A7: 6 | B7: Meccayana Rumaisha | C7: marinadwic92@gmail.com | D7: 6287824841423 | E7: Perempuan | F7: SD | G7: FULLDAY | H7: 1 | I7: INTER
A8: 7 | B8: Yumna Ishana Kamilia | C8: risnabestari@ymail.com | D8: 6287788253342 | E8: Perempuan | F8: SD | G8: FULLDAY | H8: 1 | I8: INTER
A9: 8 | B9: Alfatih Shaquile Muthaqien | C9: elisasoedarto@gmail.com | D9: 6285773242578 | E9: Laki-laki | F9: SD | G9: FULLDAY | H9: 1 | I9: INTER
A10: 9 | B10: Azkiya Hanifah Izzatunnisa | C10: ayu.wulansarimail@gmail.com | D10: 628118781707 | E10: Perempuan | F10: SD | G10: FULLDAY | H10: 1 | I10: INTER
A11: 10 | B11: Tazkiyah Assyifa Kamilah | C11: desykomalasari22@gmail.com | D11: 6282299278902 | E11: Perempuan | F11: SD | G11: FULLDAY | H11: 1 | I11: INTER
A12: 11 | B12: Safia Inara Ramadhani | C12: adilasepsi@gmail.com | D12: 6281328144041 | E12: Perempuan | F12: SD | G12: FULLDAY | H12: 1 | I12: INTER
A13: 12 | B13: Kamila Fahma Annisa | C13: putri.aditya24@gmail.com | D13: 6281218087738 | E13: Perempuan | F13: SMP | G13: FULLDAY | H13: 7 | I13: AE
A14: 13 | B14: Raidan Wahyu Ramadhan | C14: yulinamutia92@gmail.com | D14: 6287796364748 | E14: Laki-laki | F14: SD | G14: FULLDAY | H14: 1 | I14: INTER
A15: 14 | B15: Kireina Hawa Arunika Asha | C15: yanuar.erbrianto@yahoo.com | D15: 6281382149549 | E15: Perempuan | F15: SD | G15: FULLDAY | H15: 1 | I15: INTER
... A26: 25 | B26: Enzo Bilal Amitry | C26: ermitha.ps89@gmail.com | D26: 6283811103001 | E26: Laki-laki | F26: SMP | G26: FULLDAY | H26: 7 | I26: AE
A27: 26 | B27: Syaikha Zihni Althafunisa | C27: daveblue31@yahoo.co.id | D27: 628125764490 | E27: Perempuan | F27: SMA | G27: FULLDAY | H27: 10 | I27: DI | J27: IPA
A28: 27 | B28: Mikhayla Zea Sophia | C28: farid.solihin@gmail.com | D28: 6285711666234 | E28: Perempuan | F28: SD | G28: FULLDAY | H28: 1 | I28: INTER
A29: 28 | B29: Raef Muhammad Alfarezqy Ardiansyah | C29: arizka.alamsyah@gmail.com | D29: 6281281737481 | E29: Laki-laki | F29: SMP | G29: FULLDAY | H29: 7 | I29: AE
A30: 29 | B30: Xhaquille Arkha Alkhalifa | C30: herrijal@gmail.com | D30: 6281221885522 | E30: Laki-laki | F30: SD | G30: FULLDAY | H30: 1 | I30: INTER
A31: 30 | B31: Amrina Rosyada Fernita | C31: hery.ferdiansyah.hf@gmail.com | D31: 6281320735643 | E31: Perempuan | F31: SMP | G31: FULLDAY | H31: 7 | I31: AE
A32: 31 | B32: Fahd Adzka Effendy | C32: pbalqisananda@gmail.com | D32: 6282186813947 | E32: Laki-laki | F32: SD | G32: FULLDAY | H32: 1 | I32: INTER
A33: 32 | B33: Muhammad Al Ghifari | C33: ela.daphira@gmail.com | D33: 628987126979 | E33: Laki-laki | F33: SMP | G33: FULLDAY | H33: 7 | I33: AE
A34: 33 | B34: Khaleesi Putri Abdul Aziz | C34: hi.aak94@gmail.com | D34: 6281210640132 | E34: Perempuan | F34: SD | G34: FULLDAY | H34: 1 | I34: INTER
A35: 34 | B35: Ali Abdullah | C35: taufiqmt91@gmail.com | D35: 6281384661808 | E35: Laki-laki | F35: SD | G35: FULLDAY | H35: 1 | I35: INTER
A36: 35 | B36: Amaliyatul Uzma Elfawwazy | C36: moms3alfa@gmail.com | D36: 6281242237383 | E36: Perempuan | F36: SD | G36: FULLDAY | H36: 1 | I36: INTER
A37: 36 | B37: Faisal Muhammad Alfaqih | C37: hello.alifiarzk@gmail.com | D37: 6281210463708 | E37: Laki-laki | F37: SMP | G37: FULLDAY | H37: 7 | I37: AE
A38: 37 | B38: Naira Tazkia Azmi | C38: rarapurbasari2001@gmail.com | D38: 6281289505653 | E38: Perempuan | F38: SD | G38: FULLDAY | H38: 1 | I38: INTER
A39: 38 | B39: Razeen Ismail Kaffah | C39: hanifahdindaa@gmail.com | D39: 6287750228055 | E39: Laki-laki | F39: SD | G39: FULLDAY | H39: 1 | I39: INTER
... A55: 54 | B55: Sabhira Zaina Darusman | C55: skh.soraya@gmail.con | D55: 6282273403622 | E55: Perempuan | F55: SD | G55: FULLDAY | H55: 1 | I55: INTER
A56: 55 | B56: Naira Rifda Azizah | C56: ade.kosim246@gmail.com | D56: 6281510105490 | E56: Perempuan | F56: SMA | G56: FULLDAY | H56: 10 | I56: DI | J56: IPA
A57: 56 | B57: Faezya Putri Ilona Affaby | C57: anggie.wika@gmail.com | D57: 6281318731463 | E57: Perempuan | F57: SMP | G57: FULLDAY | H57: 7 | I57: AE
A58: 57 | B58: Shaquille Fatih Asshiddiq | C58: agustinheni25@gmail.com | D58: 6287786422940 | E58: Laki-laki | F58: SD | G58: FULLDAY | H58: 1 | I58: INTER
A59: 58 | B59: Abdurrahman Hanif | C59: 300109bino@gmail.com | D59: 6281219263639 | E59: Laki-laki | F59: SMA | G59: FULLDAY | H59: 10 | I59: DI | J59: IPA
A60: 59 | B60: Maryam | C60: edytalib.01@gmail.com | D60: 6282299346963 | E60: Perempuan | F60: SD | G60: FULLDAY | H60: 1 | I60: INTER
A61: 60 | B61: Iz Shahia Khadijah Azzukhruf | C61: sofyan217945@gmail.com | D61: 6285736106911 | E61: Perempuan | F61: SD | G61: FULLDAY | H61: 1 | I61: INTER
A62: 61 | B62: Raihanna Afra Zoey | C62: suricore10@gmail.com | D62: 6285711305896 | E62: Perempuan | F62: SD | G62: FULLDAY | H62: 1 | I62: INTER
A63: 62 | B63: Alula Shanum Syafazea | C63: gitapravita@gmail.com | D63: 628119330393 | E63: Perempuan | F63: SD | G63: FULLDAY | H63: 1 | I63: INTER
A64: 63 | B64: Hasna Selenia Namari | C64: naraswari.probowati@gmail.com | D64: 6282111022260 | E64: Perempuan | F64: SMP | G64: FULLDAY | H64: 7 | I64: AE
A65: 64 | B65: Kai Almaheer Gemilang Sembiring | C65: ratikawulandari80@gmail.com | D65: 6282362604075 | E65: Laki-laki | F65: SD | G65: FULLDAY | H65: 1 | I65: INTER
...

Sheet AW15
A1: NO | B1: NAMA LENGKAP | C1: EMAIL | D1: NO KONTAK YANG BISA DIHUB (gunakan 62...) | E1: JENIS KELAMIN | F1: JENJANG | G1: PROGRAM (BOARDING/FULLDAY) | H1: KELAS | I1: TYPE | J1: PEMINATAN
A2: 1 | B2: Sabil Ghazzal Assyafii | C2: yuliapermataasih@gmail.com | D2: 85717401414 | E2: Laki-laki | F2: SD | G2: Fullday | H2: 1 | I2: INTER
A3: 2 | B3: ABDULLAH ZAEN | C3: arif.setiawan16@gmail.com | D3: 81287597733 | E3: Laki-laki | F3: SD | G3: Fullday | H3: 1 | I3: INTER
A4: 3 | B4: Arkan Khalifi Haris | C4: dwinandarh@gmail.com | D4: 82113343053 | E4: Laki-laki | F4: SD | G4: Fullday | H4: 1 | I4: INTER
A5: 4 | B5: IBRAHIM MALIK AHMAD | C5: najwa.kurniawan07@gmail.com | D5: 81382526541 | E5: Laki-laki | F5: SD | G5: Fullday | H5: 1 | I5: INTER
A6: 5 | B6: ZHAFRAN TSAQIB AL MUSCHA | C6: nuzulahidayat@gmail.com | D6: 8118657519 | E6: Laki-laki | F6: SD | G6: Fullday | H6: 1 | I6: INTER
A7: 6 | B7: Hairaz Ghani Djajadisastra | C7: ekaputrihadiana@gmail.com | D7: 85381657292 | E7: Laki-laki | F7: SD | G7: Fullday | H7: 1 | I7: INTER
A8: 7 | B8: Hairaz Ghani Djajadisastra | C8: ekaputrihadiana@gmail.com | D8: 85381657292 | E8: Laki-laki | F8: SD | G8: Fullday | H8: 1 | I8: INTER
A9: 8 | B9: AHMAD NAFIZ SHOBIRIN | C9: rizmnunz@gmail.com | D9: 81282919981 | E9: Laki-laki | F9: SD | G9: Fullday | H9: 1 | I9: INTER
A10: 9 | B10: Abyzar alfizky putra | C10: stipaniangie1@gmail.com | D10: 81310753136 | E10: Laki-laki | F10: SD | G10: Fullday | H10: 1 | I10: INTER
A11: 10 | B11: Javed Ankaa Alhakim | C11: mh.nasrul@gmail.com | D11: 81224363160 | E11: Laki-laki | F11: SD | G11: Fullday | H11: 1 | I11: INT
A12: 11 | B12: Hafidz Rizky Pratama | C12: devinaputri17@gmail.com | D12: 82297715361 | E12: Laki-laki | F12: SD | G12: Fullday | H12: 1 | I12: INT
A13: 12 | B13: Kevenzovan Qaishar Andyno | C13: ndy_ap@ymail.com | D13: 82111818087 | E13: Laki-laki | F13: SD | G13: Fullday | H13: 1 | I13: INT
... A89: 88 | B89: ALMA DAVINA AYU ASMARA | C89: anitaasmara795@gmail.com | D89: 85810105619 | E89: Perempuan | F89: SMP | G89: Fullday | H89: 7 | I89: AE
A90: 89 | B90: Lidiya Safwanah | C90: aranditea@gmail.com | D90: 8812133130 | E90: Perempuan | F90: SMA | G90: Fullday | H90: 10 | I90: DI | J90: IPA
A91: 90 | B91: QISTHI HAFIZAH | C91: tasuriabiqisthi@gmail.com | D91: 8561635803 | E91: Perempuan | F91: SMA | G91: Fullday | H91: 10 | I91: DI | J91: IPA
A92: 91 | B92: Alzeena Syahirah Putri Arwi | C92: ardhianbinaputra@gmail.com | D92: 8111633414 | E92: Perempuan | F92: SMA | G92: Fullday | H92: 10 | I92: DI | J92: IPA
A93: 92 | B93: Naila shakila nur maritza | C93: kukuhhs85@gmail.com | D93: 81220814612 | E93: Perempuan | F93: SMA | G93: Fullday | H93: 10 | I93: DI | J93: IPA
A94: 93 | B94: Shafa Nur Aisyah | C94: sabardarsono4@gmail.com | D94: 81283302722 | E94: Perempuan | F94: SMA | G94: Fullday | H94: 10 | I94: DI | J94: IPA
A95: 94 | B95: Faradisa khumairah ramadhani | C95: rosidatululyah@gmail.com | D95: 81311070363 | E95: Perempuan | F95: SMA | G95: Fullday | H95: 10 | I95: DI | J95: IPA
A96: 95 | B96: Najma Nainawa | C96: rida.suci@gmail.com | D96: 87888432009 | E96: Perempuan | F96: SMA | G96: Fullday | H96: 10 | I96: DI | J96: IPS
A97: 96 | B97: Hashifah Hanna | C97: abuulayya@gmail.com | D97: 8569034398 | E97: Perempuan | F97: SMA | G97: Fullday | H97: 10 | I97: DI | J97: IPA
E99: SD | F99: =COUNTIF($F$2:$F$97,E99) -> 62
E100: SMP | F100: =COUNTIF($F$2:$F$97,E100) -> 26
E101: SMA | F101: =COUNTIF($F$2:$F$97,E101) -> 8
F102: =SUM(F99:F101) -> 96

Sheet AW16
A1: NO | B1: NAMA LENGKAP | C1: EMAIL | D1: NO KONTAK YANG BISA DIHUB (gunakan 62...) | E1: JENIS KELAMIN | F1: JENJANG | G1: PROGRAM (BOARDING/FULLDAY) | H1: KELAS | I1: TYPE | J1: PEMINATAN
A2: 1 | B2: NARESWARI HANA KHAIRA | C2: izaghip.is@gmail.com | D2: 6282113811381 | E2: PEREMPUAN | F2: SMP | G2: BOARDING | H2: 7 | I2: SMP BOARDING | J2: AMERICA EUROPE
A3: 2 | B3: DINI KHAERA ZAITUN | C3: triindriasih.95@gmail.com | D3: 6281386875705 | E3: PEREMPUAN | F3: SMP | G3: FULLDAY | H3: 7 | I3: SMP FULLDAY | J3: AMERICA EUROPE
A4: 3 | B4: KHANSA KHAIRANA KARIM | C4: k.yossyamalia@gmail.com | D4: 628111920191 | E4: PEREMPUAN | F4: SMP | G4: FULLDAY | H4: 7 | I4: SMP FULLDAY | J4: AMERICA EUROPE
A5: 4 | B5: HAURA ATHIRAH KAMALA TSABITA | C5: ayu.mumpuni07@gmail.com | D5: 6281299884884 | E5: PEREMPUAN | F5: SD | G5: FULLDAY | H5: 1 | I5: 1 | J5: INTERNATIONAL
A6: 5 | B6: ATHAYA SIERRA DARMAN | C6: naziefa82@gmail.com | D6: 628158985351 | E6: PEREMPUAN | F6: SMA | G6: FULLDAY | H6: 10 | I6: SMA FULLDAY | J6: AMERICA EUROPE
A7: 6 | B7: EYUNNA BATARI NANDITYA | C7: aditya.ekacandra@gmail.com | D7: 6281298881055 | E7: PEREMPUAN | F7: SMP | G7: FULLDAY | H7: 7 | I7: SMP FULLDAY | J7: AMERICA EUROPE
A8: 7 | B8: SHAHIA NAHRASYIYAH ARIEF | C8: sarahsyauqina06@gmail.com | D8: 6281380048440 | E8: PEREMPUAN | F8: SD | G8: FULLDAY | H8: 1 | I8: 1 | J8: INTERNATIONAL
A9: 8 | B9: MUHAMMAD ZAIN YUSUF AL AYUBI | C9: evi.civileng@gmail.com | D9: 6281932329444 | E9: LAKI-LAKI | F9: SD | G9: FULLDAY | H9: 1 | I9: 1 | J9: INTERNATIONAL
A10: 9 | B10: TEUKU MOHAMMAD ARFA | C10: rulisguntari@gmail.com | D10: 6281283669211 | E10: LAKI-LAKI | F10: SD | G10: FULLDAY | H10: 1 | I10: 1 | J10: INTERNATIONAL
A11: 10 | B11: MUSA MUHAMMAD | C11: novinafirlia@yahoo.com | D11: 6281219709317 | E11: LAKI-LAKI | F11: SD | G11: FULLDAY | H11: 1 | I11: 1 | J11: INTERNATIONAL
A12: 11 | B12: MUHAMMAD SYAUQI FUTAKI ASH SHIDDIQI | C12: meitatirtasari1@gmail.com | D12: 6281293437456 | E12: LAKI-LAKI | F12: SD | G12: FULLDAY | H12: 1 | I12: 1 | J12: INTERNATIONAL
A13: 12 | B13: ALQA RAFFAZA DIEGA | C13: hasanahmahfud23@gmail.com | D13: 6281314843898 | E13: LAKI-LAKI | F13: SD | G13: FULLDAY | H13: 1 | I13: 1 | J13: INTERNATIONAL
A14: 13 | B14: AURORA SYAKILLA MEDINA ALI | C14: siwi.vera19@gmail.com | D14: 6281290093602 | E14: PEREMPUAN | F14: SD | G14: FULLDAY | H14: 1 | I14: 1 | J14: INTERNATIONAL
A15: 14 | B15: THALHAH | C15: sherlyaprililianty@yahoo.com | D15: 6282122333011 | E15: LAKI-LAKI | F15: SD | G15: FULLDAY | H15: 1 | I15: 1 | J15: INTERNATIONAL
A16: 15 | B16: CHAIRA AZZURA MECCA | C16: marinofebriyana@gmail.com | D16: 6285212588854 | E16: PEREMPUAN | F16: SD | G16: FULLDAY | H16: 1 | I16: 1 | J16: INTERNATIONAL
A17: 16 | B17: MARYAM WIBISANA | C17: gitaindahputri@gmail.com | D17: 6287777662164 | E17: PEREMPUAN | F17: SD | G17: FULLDAY | H17: 1 | I17: 1 | J17: INTERNATIONAL
A18: 17 | B18: ABINAYA BAHY AL GHAZEE | C18: vidyahanesty@gmail.com | D18: 628561000627 | E18: LAKI-LAKI | F18: SD | G18: FULLDAY | H18: 1 | I18: 1 | J18: INTERNATIONAL
A19: 18 | B19: ADIA SALMA HUMAIRA | C19: larasatiimpianita9248@gmail.com | D19: 6281218110700 | E19: PEREMPUAN | F19: SMP | G19: FULLDAY | H19: 7 | I19: SMP FULLDAY | J19: AMERICA EUROPE
A20: 19 | B20: ADIA RAHMA SALSABILA | C20: larasatiimpianita9248@gmail.com | D20: 6281218110700 | E20: PEREMPUAN | F20: SMP | G20: FULLDAY | H20: 7 | I20: SMP FULLDAY | J20: AMERICA EUROPE
A21: 20 | B21: MUHAMMAD ZAFRAN ALI | C21: arya.nugraha88@gmail.com | D21: 6287777087171 | E21: LAKI-LAKI | F21: SD | G21: FULLDAY | H21: 1 | I21: 1 | J21: INTERNATIONAL
A22: 21 | B22: ZAYID BARAKA | C22: adde1608riyatna@gmail.com | D22: 6282140420772 | E22: LAKI-LAKI | F22: SD | G22: FULLDAY | H22: 1 | I22: 1 | J22: INTERNATIONAL
A23: 22 | B23: SALMA ALESHA RAMDHANI | C23: nurafianti31@gmail.com | D23: 628212115637 | E23: PEREMPUAN | F23: SD | G23: FULLDAY | H23: 1 | I23: 1 | J23: INTERNATIONAL
A24: 23 | B24: ARLAN BANYYU ABIYANAK | C24: saniadara2020@gmail.com | D24: 62859106797344 | E24: LAKI-LAKI | F24: SD | G24: FULLDAY | H24: 3 | I24: 3 | J24: INTERNATIONAL
A25: 24 | B25: MUHAMMAD UTSMAN WINATA | C25: novart18@gmail.com | D25: 6285691650837 | E25: LAKI-LAKI | F25: SD | G25: FULLDAY | H25: 1 | I25: 1 | J25: INTERNATIONAL
A26: 25 | B26: INARA AYUDIA KURNIANSYAH | C26: rosariasih88@gmail.com | D26: 6281294648051 | E26: PEREMPUAN | F26: SMP | G26: FULLDAY | H26: 7 | I26: 7 | J26: AMERICA EUROPE
A27: 26 | B27: HAWA NUR AISYA AURORA | C27: darayunda25@gmail.com | D27: 628119888625 | E27: PEREMPUAN | F27: SD | G27: FULLDAY | H27: 1 | I27: 1 | J27: INTERNATIONAL
A28: 27 | B28: KHALID ARZANKA BASUKI | C28: annisahalim02@gmail.com | D28: 628111005422 | E28: LAKI-LAKI | F28: SD | G28: FULLDAY | H28: 1 | I28: 1 | J28: INTERNATIONAL
A29: 28 | B29: FAYZA SHEZAN BANAFSHA | C29: vinawidyanti11@gmail.com | D29: 628128070521 | E29: PEREMPUAN | F29: SD | G29: FULLDAY | H29: 1 | I29: 1 | J29: INTERNATIONAL
A30: 29 | B30: ALYA AZKADINA | C30: Ayu.puspitasari87@gmail.com | D30: 6285697908918 | E30: PEREMPUAN | F30: SMP | G30: FULLDAY | H30: 7 | I30: 7 | J30: AMERICA EUROPE
A31: 30 | B31: ALEENA SHASMEEN ANZALNA | C31: elma.amalia@gmail.com | D31: 628111672929 | E31: PEREMPUAN | F31: SMP | G31: FULLDAY | H31: 7 | I31: 7 | J31: AMERICA EUROPE
A32: 31 | B32: SABRINA AFSHEENA RIZKY | C32: elsyaputririzky13@gmail.com | D32: 6285778979723 | E32: PEREMPUAN | F32: SMP | G32: FULLDAY | H32: 7 | I32: 7 | J32: AMERICA EUROPE
... A34: 33 | B34: SORA ABRIANNA JENNA | C34: imeldaameliya@yahoo.com | D34: 6281288046111 | E34: PEREMPUAN | F34: SD | G34: FULLDAY | H34: 1 | I34: 1 | J34: INTERNATIONAL
A35: 34 | B35: LUBNA AZALEA QIANDRA LATIF | C35: Azalea.hijaab@gmail.com | D35: 6282213071348 | E35: PEREMPUAN | F35: SMP | G35: FULLDAY | H35: 7 | I35: SMP FULLDAY | J35: AMERICA EUROPE
A36: 35 | B36: UWAIS ALKALIFI | C36: ranigusrianto2@gmail.com | D36: 6289623388137 | E36: LAKI-LAKI | F36: SD | G36: FULLDAY | H36: 1 | I36: 1 | J36: INTERNATIONAL
A37: 36 | B37: USTMAN ABDULLAH | C37: 100065.nur@gmail.com | D37: 628111897910 | E37: LAKI-LAKI | F37: SD | G37: FULLDAY | H37: 1 | I37: 1 | J37: INTERNATIONAL
A38: 37 | B38: ABDULLAH KAFFAH | C38: mohai_refri@yahoo.com | D38: 6281282058698 | E38: LAKI-LAKI | F38: SMP | G38: FULLDAY | H38: 7 | I38: SMP FULLDAY | J38: AMERICA EUROPE
A39: 38 | B39: MUHAMMAD NUFAIL ERDOGAN | C39: cut_ara@yahoo.com | D39: 6281212969636 | E39: LAKI-LAKI | F39: SD | G39: FULLDAY | H39: 1 | I39: 1 | J39: INTERNATIONAL
A40: 39 | B40: ELVIRA SUGIONO | C40: emiwahyuningsih464@gmail.com | D40: 6281317055652 | E40: PEREMPUAN | F40: SMP | G40: FULLDAY | H40: 7 | I40: SMP FULLDAY | J40: AMERICA EUROPE
A41: 40 | B41: FARZANA ZASKIA ZAHRA | C41: daralaksmitaayuningtyas@gmail.com | D41: 6285691718267 | E41: PEREMPUAN | F41: SMP | G41: FULLDAY | H41: 7 | I41: SMP FULLDAY | J41: AMERICA EUROPE
...

Sheet AW20
A1: NO | B1: NAMA LENGKAP | C1: EMAIL | D1: NO KONTAK YANG BISA DIHUB (gunakan 62...) | E1: JENIS KELAMIN | F1: JENJANG | G1: PROGRAM (BOARDING/FULLDAY) | H1: KELAS | I1: TYPE | J1: PEMINATAN
A2: 1
A3: 2
A4: 3
A5: 4
A6: 5
A7: 6
A8: 7
A9: 8
A10: 9
A11: 10
A12: 11
A13: 12
A14: 13

Sheet AW21
A1: NO | B1: NAMA LENGKAP | C1: EMAIL | D1: NO KONTAK YANG BISA DIHUB (gunakan 62...) | E1: JENIS KELAMIN | F1: JENJANG | G1: PROGRAM (BOARDING/FULLDAY) | H1: KELAS | I1: TYPE | J1: PEMINATAN
A2: 1
A3: 2
A4: 3
A5: 4
A6: 5
A7: 6
A8: 7
A9: 8
A10: 9
A11: 10
A12: 11
A13: 12
A14: 13

Sheet AW22
A1: NO | B1: NAMA LENGKAP | C1: EMAIL | D1: NO KONTAK YANG BISA DIHUB (gunakan 62...) | E1: JENIS KELAMIN | F1: JENJANG | G1: PROGRAM (BOARDING/FULLDAY) | H1: KELAS | I1: TYPE | J1: PEMINATAN
A2: 1
A3: 2
A4: 3
A5: 4
A6: 5
A7: 6
A8: 7
A9: 8
A10: 9
A11: 10
A12: 11
A13: 12
A14: 13

Sheet AW23
A1: NO | B1: NAMA LENGKAP | C1: EMAIL | D1: NO KONTAK YANG BISA DIHUB (gunakan 62...) | E1: JENIS KELAMIN | F1: JENJANG | G1: PROGRAM (BOARDING/FULLDAY) | H1: KELAS | I1: TYPE | J1: PEMINATAN
A2: 1
A3: 2
A4: 3
A5: 4
A6: 5
A7: 6
A8: 7
A9: 8
A10: 9
A11: 10
A12: 11
A13: 12
A14: 13

Sheet AW24
A1: NO | B1: NAMA LENGKAP | C1: EMAIL | D1: NO KONTAK YANG BISA DIHUB (gunakan 62...) | E1: JENIS KELAMIN | F1: JENJANG | G1: PROGRAM (BOARDING/FULLDAY) | H1: KELAS | I1: TYPE | J1: PEMINATAN
A2: 1
A3: 2
A4: 3
A5: 4
A6: 5
A7: 6
A8: 7
A9: 8
A10: 9
A11: 10
A12: 11
A13: 12
A14: 13

Sheet AW28
A1: NO | B1: NAMA LENGKAP | C1: EMAIL | D1: NO KONTAK YANG BISA DIHUB (gunakan 62...) | E1: JENIS KELAMIN | F1: JENJANG | G1: PROGRAM (BOARDING/FULLDAY) | H1: KELAS | I1: TYPE | J1: PEMINATAN
A2: 1 | B2: IDRIS TAKA RASYIQ ABI MULYO | C2: mulyono_wibowo@yahoo.co.id | D2: 89608831239 | E2: Laki-laki | F2: SD | G2: FULLDAY | H2: 5 | J2: INTER
A3: =SUM(A2+1) -> 2 | B3: Gavin Azlan Arridho | C3: fadhilaelfahmi@gmail.com | D3: 085274992201 | E3: Laki-laki | F3: SD | G3: FULLDAY | H3: 1 | J3: INTER
A4: =SUM(A3+1) -> 3 | B4: Al Fatih Zubair Kahfi | C4: putrisahara91@gmail.com | D4: 08111444199 | E4: Laki-laki | F4: SD | G4: FULLDAY | H4: 1 | J4: INTER
A5: =SUM(A4+1) -> 4 | B5: Abbas As Sahl | C5: jeni.nurwijaya87@gmail.com | D5: 085719885778 | E5: Laki-laki | F5: SD | G5: FULLDAY | H5: 3 | J5: INTER
A6: =SUM(A5+1) -> 5 | B6: Ibrahim | C6: febrianu1502.rf@gmail.com | D6: 082112732626 | E6: Laki-laki | F6: SD | G6: FULLDAY | H6: 3 | J6: INTER
A7: =SUM(A6+1) -> 6 | B7: Kenzie Hamizan Atani | C7: fristasahresti01@gmail.com | D7: 082388133313 | E7: Laki-laki | F7: SD | G7: FULLDAY | H7: 2 | J7: INTER
A8: =SUM(A7+1) -> 7 | B8: RYUGA ALTARIA ARIFIANDI | C8: putrikartikasari05@gmail.com | D8: 08112220910 | E8: Laki-laki | F8: SD | G8: FULLDAY | H8: 1 | J8: INTER
A9: =SUM(A8+1) -> 8 | B9: AZKARA MUHAMMAD RAGISQY | C9: ARIFBANDANGKURNIA@GMAIL.COM | D9: 085881772308 | E9: Laki-laki | F9: SD | G9: FULLDAY | H9: 1 | J9: INTER
A10: =SUM(A9+1) -> 9 | B10: Zinedine Zhafran Rafisqy | C10: sitiaisyahn21@gmail.com | D10: 081319074651 | E10: Laki-laki | F10: SD | G10: FULLDAY | H10: 1 | J10: INTER
A11: =SUM(A10+1) -> 10 | B11: Umar Hamilul Quran | C11: maedasyifaf20@gmail.com | D11: 082225232568 | E11: Laki-laki | F11: SD | G11: FULLDAY | H11: 1 | J11: INTER
A12: =SUM(A11+1) -> 11 | B12: Abdul Hamid Alfatih | C12: ygustiawan@gmail.com | D12: 0816821055 | E12: Laki-laki | F12: SD | G12: FULLDAY | H12: 1 | J12: INTER
A13: =SUM(A12+1) -> 12 | B13: Muhammad Rafa Mulyana | C13: revamita@gmail.com | D13: 08118229292 | E13: Laki-laki | F13: SD | G13: FULLDAY | H13: 1 | J13: INTER
A14: =SUM(A13+1) -> 13 | B14: Athalla Nareshwara Hartoyo | C14: pandhutomo@gmail.com | D14: 08111110190 | E14: Laki-laki | F14: SD | G14: FULLDAY | H14: 3 | J14: INTER
A15: =SUM(A14+1) -> 14 | B15: Eirsyad Habibi Darmawan | C15: ami.yati2011@gmail.com | D15: 081283018836 | E15: Laki-laki | F15: SD | G15: FULLDAY | H15: 2 | J15: INTER
A16: =SUM(A15+1) -> 15 | B16: Aizar Falah Kusumawardhana | C16: dkusumawardhana@icloud.com | D16: 816761988 | E16: Laki-laki | F16: SD | G16: FULLDAY | H16: 2 | J16: INTER
A17: =SUM(A16+1) -> 16 | B17: Maheera Aqsa Mumtazocta | C17: pertiwiidew@gmail.com | D17: 81298064656 | E17: Perempuan | F17: SD | G17: FULLDAY | H17: 1 | J17: INTER
A18: =SUM(A17+1) -> 17 | B18: Neyna Maryam Safa | C18: rukmanalia022@gmail.com | D18: 87775788222 | E18: Perempuan | F18: SD | G18: FULLDAY | H18: 4 | J18: INTER
A19: =SUM(A18+1) -> 18 | B19: Hafshah | C19: ayu.dianpermatasari.ad@gmail.com | D19: 85740466232 | E19: Perempuan | F19: SD | G19: FULLDAY | H19: 1 | J19: INTER
A20: =SUM(A19+1) -> 19 | B20: Janaahaka Shaima Hartoyo | C20: pandhutomo@gmail.com | D20: 8111110190 | E20: Perempuan | F20: SD | G20: FULLDAY | H20: 1 | J20: INTER
A21: =SUM(A20+1) -> 20 | B21: Lamia Arundati Handoyo | C21: diva.santika89@gmail.com | D21: 81380172763 | E21: Perempuan | F21: SD | G21: FULLDAY | H21: 5 | J21: INTER
A22: =SUM(A21+1) -> 21 | B22: Azizah Khoirunniswah | C22: dhochaniago@gmail.com | D22: 081297004000 | E22: Perempuan | F22: SD | G22: FULLDAY | H22: 1 | J22: INTER
A23: =SUM(A22+1) -> 22 | B23: Azzura Eisha Arlita | C23: riamanggalita23@gmail.com | D23: 085694175252 | E23: Perempuan | F23: SD | G23: FULLDAY | H23: 1 | J23: INTER
A24: =SUM(A23+1) -> 23 | B24: QEISYA RIZKY KUSUMA IZZATUNNISA | C24: rizkynuralfushinna@gmail.com | D24: 085648024605 | E24: Perempuan | F24: SD | G24: FULLDAY | H24: 1 | J24: INTER
A25: =SUM(A24+1) -> 24 | B25: Maryam Falisha Qurrota a'yun | C25: winda.septyani1296@gmail.com | D25: 081538729998 | E25: Perempuan | F25: SD | G25: FULLDAY | H25: 1 | J25: INTER
A26: =SUM(A25+1) -> 25 | B26: Aqila Hafeeza Wardana | C26: miafitriyah@gmail.com | D26: 085691282887 | E26: Perempuan | F26: SD | G26: FULLDAY | H26: 1 | J26: INTER
A27: =SUM(A26+1) -> 26 | B27: Hafeezha Izzati Kamaryam | C27: vika.septiyani@gmail.com | D27: 081311157715 | E27: Perempuan | F27: SD | G27: FULLDAY | H27: 1 | J27: INTER
A28: =SUM(A27+1) -> 27 | B28: Maryam | C28: uswahalvup1011@gmail.com | D28: 085232996944 | E28: Perempuan | F28: SD | G28: FULLDAY | H28: 1 | J28: INTER
A29: =SUM(A28+1) -> 28 | B29: HANNAH | C29: minibitesbite@gmail.com | D29: 081320908228 | E29: Perempuan | F29: SD | G29: FULLDAY | H29: 2 | J29: INTER
A30: =SUM(A29+1) -> 29 | B30: Shofiyyah Huwaida Yumna | C30: dwiamandarany@gmail.com | D30: 082298060990 | E30: Perempuan | F30: SD | G30: FULLDAY | H30: 3 | J30: INTER
A31: =SUM(A30+1) -> 30 | B31: AYASHA SALEEHA AZEEMA | C31: dkusumawardhana@icloud.com | D31: 816761988 | E31: Perempuan | F31: SD | G31: FULLDAY | H31: 5 | J31: INTER
A32: =SUM(A31+1) -> 31 | B32: Khaula Hawa Tsabitah | C32: rozaq.2808@gmail.com | D32: 811993308 | E32: Perempuan | F32: SD | G32: FULLDAY | H32: 1 | J32: INTER
A33: =SUM(A32+1) -> 32 | B33: Sami zuhur alfalih | C33: onlystevieayu@yahoo.com | D33: 87888196777 | E33: Laki-laki | F33: SMP | G33: FULLDAY | H33: 7 | J33: AE
A34: =SUM(A33+1) -> 33 | B34: ABRAHAM AZKA RASYIQ ABI MULYO | C34: mulyono_wibowo@yahoo.co.id | D34: 89608831239 | E34: Laki-laki | F34: SMP | G34: FULLDAY | H34: 7 | J34: AE
A35: =SUM(A34+1) -> 34 | B35: MUHAMMAD BILAL HABILULLAH ARIFIN | C35: linaibunyanabila@gmail.com | D35: 82114324294 | E35: Laki-laki | F35: SMP | G35: FULLDAY | H35: 7 | J35: AE
A36: =SUM(A35+1) -> 35 | B36: Aktam Jabil Marhendra | C36: dimasmarhendra1@gmail.com | D36: 087876085760 | E36: Laki-laki | F36: SMP | G36: FULLDAY | H36: 7 | J36: AE
A37: =SUM(A36+1) -> 36 | B37: GHIBRAN DARY ABIYYU | C37: renisutoyo@gmail.com | D37: 082124453161 | E37: Laki-laki | F37: SMP | G37: FULLDAY | H37: 7 | J37: AE
A38: =SUM(A37+1) -> 37 | B38: MUHAMMAD ARSYA ADZAHWAN | C38: ukedahlia1@gmail.com | D38: 087880501900 | E38: Laki-laki | F38: SMP | G38: FULLDAY | H38: 7 | J38: AE
A39: =SUM(A38+1) -> 38 | B39: Mufid Khaizuran Indra | C39: niceikha@gmail.com | D39: 081314921552 | E39: Laki-laki | F39: SMP | G39: FULLDAY | H39: 7 | J39: AE
A40: =SUM(A39+1) -> 39 | B40: Ghaly Alfahrizi Evendi | C40: endahaydha17@gmail.com | D40: 081296577477 | E40: Laki-laki | F40: SMP | G40: FULLDAY | H40: 7 | J40: AE
...

Sheet AW29
A1: NO | B1: NAMA LENGKAP | C1: EMAIL | D1: NO KONTAK YANG BISA DIHUB (gunakan 62...) | E1: JENIS KELAMIN | F1: JENJANG | G1: PROGRAM (BOARDING/FULLDAY) | H1: KELAS | I1: TYPE | J1: PEMINATAN
A2: 1 | B2: DAFFA FEBRIYANDRA | C2: febyfitria29@gmail.com | D2: 62895334862097 | E2: LAKI-LAKI | F2: SD | G2: FULLDAY | H2: 1 | J2: INTER
A3: 2 | B3: SANGSHAKA SAGARA YUNAS | C3: anggunpangesti@gmail.com | D3: 6285655633353 | E3: LAKI-LAKI | F3: SD | G3: FULLDAY | H3: 1 | J3: INTER
A4: 3 | B4: KAMAYEL IBNU SOEBEKTI | C4: adistinovira@gmail.com | D4: 6281294110882 | E4: LAKI-LAKI | F4: SD | G4: FULLDAY | H4: 1 | J4: INTER
A5: 4 | B5: DHIRAR IBRAHIM SAYOGO | C5: febrikaputrosayogo@gmail.com | D5: 6282298868181 | E5: LAKI-LAKI | F5: SD | G5: FULLDAY | H5: 1 | J5: INTER
A6: 5 | B6: UMAR ADSKHAN ATHAFARIZ | C6: hariprasetyanugraha@gmail.com | D6: 6285892227174 | E6: LAKI-LAKI | F6: SD | G6: FULLDAY | H6: 1 | J6: INTER
A7: 6 | B7: ADAM DZUHAIRI ASIA | C7: vitayuanu@gmail.com | D7: 6281916122472 | E7: LAKI-LAKI | F7: SD | G7: FULLDAY | H7: 1 | J7: INTER
A8: 7 | B8: BAGAS ABDURRAHMAN EMIRSATYA | C8: qreinaalt@gmail.com | D8: 6282214678536 | E8: LAKI-LAKI | F8: SD | G8: FULLDAY | H8: 1 | J8: INTER
A9: 8 | B9: ALHANAN MUHAMMAD SHIDQI | C9: tri.mulyani2704@gmail.com | D9: 6281282721585 | E9: LAKI-LAKI | F9: SD | G9: FULLDAY | H9: 1 | J9: INTER
A10: 9 | B10: ALGHIAN ZINEDINE KHAIR | C10: amarizka.t@gmail.com | D10: 6281287833720 | E10: LAKI-LAKI | F10: SD | G10: FULLDAY | H10: 1 | J10: INTER
A11: 10 | B11: AR RAYYAN IBRAHIM | C11: trioferdyanto@gmail.com | D11: 6281382221751 | E11: LAKI-LAKI | F11: SD | G11: FULLDAY | H11: 1 | J11: INTER
A12: 11 | B12: MUHAMMAD ABQORY AL-AFASY | C12: primasariagustina07@gmail.com | D12: 6289654725596 | E12: LAKI-LAKI | F12: SD | G12: FULLDAY | H12: 1 | J12: INTER
A13: 12 | B13: HISYAM ZAKIR ATHALLAH | C13: khabi.faizal@gmail.com | D13: 6287774663637 | E13: LAKI-LAKI | F13: SD | G13: FULLDAY | H13: 1 | J13: INTER
... A70: 69 | B70: ZAKI MAGNIFICO HIDAYAT | C70: nurul.fjh@gmail.com | D70: 628122799945 | E70: LAKI-LAKI | F70: SMA | G70: FULLDAY | H70: 10 | J70: DI IPA
A71: 70 | B71: NI PUTU CALLISTA ALMAHYRA | C71: desvita.rosana@gmail.com | D71: 082219004207 | E71: PEREMPUAN | F71: SMA | G71: FULLDAY | H71: 10 | J71: AE IPA
A72: 71 | B72: AISHA RAIHANUM JASMINE ARIYANTO | C72: rizkihegarayu@gmail.com | D72: 081213662234 | E72: PEREMPUAN | F72: SMA | G72: FULLDAY | H72: 10 | J72: DI IPS
A73: 72 | B73: ZIHAN SYAHDIRA ELWAFA | C73: dianarafiah81@gmail.com | D73: 6281371560677 | E73: PEREMPUAN | F73: SMA | G73: FULLDAY | H73: 10 | J73: DI IPS
A74: 73 | B74: KHANSA AMIRAH LATHIFAH | C74: ummu.finifasa1995@gmail.com | D74: 6281915346342 | E74: PEREMPUAN | F74: SMA | G74: FULLDAY | H74: 10 | J74: AE IPS
A75: 74 | B75: AYSHAH TSABITA | C75: widya.rostin@gmail.com | D75: 6281295466462 | E75: PEREMPUAN | F75: SMA | G75: FULLDAY | H75: 10 | J75: DI IPA
E77: SD | F77: =COUNTIF($F$2:$F$75,E77) -> 43
E78: SMP | F78: =COUNTIF($F$2:$F$75,E78) -> 22
E79: SMA | F79: =COUNTIF($F$2:$F$75,E79) -> 9
F80: =SUM(F77:F79) -> 74

Sheet AW30
A1: NO | B1: NAMA LENGKAP | C1: EMAIL | D1: NO KONTAK YANG BISA DIHUB (gunakan 62...) | E1: JENIS KELAMIN | F1: JENJANG | G1: PROGRAM (BOARDING/FULLDAY) | H1: KELAS | I1: TYPE | J1: PEMINATAN
A2: 1
A3: 2
A4: 3
A5: 4
A6: 5
A7: 6
A8: 7
A9: 8
A10: 9
A11: 10
A12: 11
A13: 12
A14: 13

Sheet AW31
A1: NO | B1: NAMA LENGKAP | C1: EMAIL | D1: NO KONTAK YANG BISA DIHUB (gunakan 62...) | E1: JENIS KELAMIN | F1: JENJANG | G1: PROGRAM (BOARDING/FULLDAY) | H1: KELAS | I1: TYPE | J1: PEMINATAN
A2: 1 | B2: MUHAMMAD FATIH ABDURRAHMAN | C2: muhammadhaniefihsan@gmail.com | D2: wa.me/6287731073105 | E2: Laki-laki | F2: SD | G2: FULLDAY | H2: 1 | J2: INTER
A3: 2 | B3: ARCELIO HUSEIN | C3: priskaanastasiad26@gmail.com | D3: wa.me/6289524131385 | E3: Laki-laki | F3: SD | G3: FULLDAY | H3: 1 | J3: INTER
A4: 3 | B4: MAYZA AGHNIA IZZATUNNISA | C4: imamarief20@gmail.com | D4: wa.me/6281390000525 | E4: Perempuan | F4: SD | G4: FULLDAY | H4: 1 | J4: INTER
A5: 4 | B5: ALFATH SAID ABDULAZIZ | C5: hamdan.nfs@gmail.com | D5: wa.me/6282116665772 | E5: Laki-laki | F5: SD | G5: FULLDAY | H5: 1 | J5: INTER
A6: 5 | B6: YLEVA YASLYN PURBA | C6: bunbunga24@gmail.com | D6: wa.me/628988592725 | E6: Perempuan | F6: SD | G6: FULLDAY | H6: 1 | J6: INTER
A7: 6 | B7: ABDURRAHMAN SYAFIQ MUHAMMAD | C7: aniratnasari1994@gmail.com | D7: wa.me/6281316166456 | E7: Laki-laki | F7: SD | G7: FULLDAY | H7: 1 | J7: INTER
A8: 7 | B8: SYAFIQ MUHAMMAD AL BARRA | C8: dianpertiwi0805@gmail.com | D8: wa.me/6282213708424 | E8: Laki-laki | F8: SD | G8: FULLDAY | H8: 1 | J8: INTER
A9: 8 | B9: ZIVANA SABHIRA AL ROSYID | C9: siwindaalrosyid@gmail.com | D9: wa.me/6281283431622 | E9: Perempuan | F9: SD | G9: FULLDAY | H9: 1 | J9: INTER
A10: 9 | B10: FATIMAH KHAIRUNNISA AZIZAH | C10: 3ndahpurnamasar1@gmail.com | D10: wa.me/6285718200960 | E10: Perempuan | F10: SD | G10: FULLDAY | H10: 1 | J10: INTER
A11: 10 | B11: ALEETTA SHAKIRA NASHABA | C11: prittadesica@gmail.com | D11: wa.me/6281298787599 | E11: Perempuan | F11: SD | G11: FULLDAY | H11: 1 | J11: INTER
A12: 11 | B12: ARSYIKA RAFANDA | C12: riyadyesha@gmail.com | D12: wa.me/6285780504370 | E12: Perempuan | F12: SD | G12: FULLDAY | H12: 1 | J12: INTER
A13: 12 | B13: MUHAMMAD REYHAN ALFATHAN | C13: rizkaalfiyanaa@gmail.com | D13: wa.me/6281372885122 | E13: Laki-laki | F13: SD | G13: FULLDAY | H13: 1 | J13: INTER
... A22: 21 | B22: RAYINA AMTAZA SYAHLA | C22: nsuryaningsih1464@gmail.com | D22: wa.me/6285218442850 | E22: Perempuan | F22: SMA | G22: FULLDAY | H22: 10 | J22: AE
A23: 22
A24: 23 | E24: SD | F24: =COUNTIF($F$2:$F$22,E24) -> 16
A25: 24 | E25: SMP | F25: =COUNTIF($F$2:$F$22,E25) -> 3
A26: 25 | E26: SMA | F26: =COUNTIF($F$2:$F$22,E26) -> 2
F27: =SUM(F24:F26) -> 21

Sheet AW32
A1: NO | B1: NAMA LENGKAP | C1: EMAIL | D1: NO KONTAK YANG BISA DIHUB (gunakan 62...) | E1: JENIS KELAMIN | F1: JENJANG | G1: PROGRAM (BOARDING/FULLDAY) | H1: KELAS | I1: TYPE | J1: PEMINATAN
A2: 1 | B2: Primsha Agiyna Putri Sitepu | C2: febri.sitepu@gmail.com | D2: 085211166012 | E2: Perempuan | F2: SD | G2: Fullday | H2: 1 | J2: INTER
A3: 2 | B3: Alma Humaira | C3: hermantrans@gmail.com | D3: 085882119429 | E3: Perempuan | F3: SMP | G3: Fullday | H3: 7 | J3: INTER
A4: 3 | B4: Haidar Kiano Putra | C4: retitamaha89@gmail.com | D4: 081585173749 | E4: Laki-laki | F4: SD | G4: Fullday | H4: 5 | J4: INTER
A5: 4 | B5: Aisyah | C5: septiyantikurniya@gmail.com | D5: 081219266087 | E5: Perempuan | F5: SD | G5: Fullday | H5: 1 | J5: INTER
A6: 5 | B6: Hiromi | C6: izzaty_fahmi@yahoo.co.id | D6: 081289199549 | E6: Perempuan | F6: SD | G6: Fullday | H6: 1 | J6: INTER
A7: 6 | B7: Khaula Yumna Steffanov | C7: radityashinta@gmail.com | D7: 081316801394 | E7: Perempuan | F7: SD | G7: Fullday | H7: 1 | J7: INTER
A8: 7 | B8: Dzakir Yusuf Nattalegawa | C8: gita.soraya275@gmail.com | D8: 08998027590 | E8: Laki-laki | F8: SMP | G8: Fullday | H8: 7 | J8: INTER
A9: 8 | B9: Nabil Khoiruzzadittaqwa | C9: utama.putra01@yahoo.com | D9: 082298384119 | E9: Laki-laki | F9: SD | G9: Fullday | H9: 1 | J9: INTER
A10: 9 | B10: CHIARRA SABRINA SRILICIA | C10: csscrf.153@gmail.com | D10: 0811815317 | E10: Perempuan | F10: SMP | G10: Fullday | H10: 7 | J10: INTER
A11: 10 | B11: Alesha Humairah hafizah | C11: auliamst@ymail.com | D11: 081287005717 | E11: Perempuan | F11: SD | G11: Fullday | H11: 1 | J11: INTER
A12: 11 | B12: Elfawwaz rayyan hafizt | C12: auliamst@ymail.com | D12: 081287005717 | E12: Laki-laki | F12: SD | G12: Fullday | H12: 1 | J12: INTER
A13: 12 | B13: Raniah Thariq Alwyni | C13: att.thaariq@gmail.com | D13: 081280535354 | E13: Perempuan | F13: SMA | G13: Fullday | H13: 10 | J13: INTER
... A81: 80 | B81: Yasmin Mafaza | C81: fitriamutia@gmail.com | D81: 08111941990 | E81: Perempuan | F81: SD | G81: Fullday | H81: 1 | J81: INTER
E83: SD | F83: =COUNTIF($F$2:$F$81,E83) -> 44
E84: SMP | F84: =COUNTIF($F$2:$F$81,E84) -> 29
E85: SMA | F85: =COUNTIF($F$2:$F$81,E85) -> 7
F86: =SUM(F83:F85) -> 80
